<?xml version="1.0" encoding="utf-8"?>
<!-- This URDF was automatically created by SolidWorks to URDF Exporter! Originally created by Stephen Brawner (brawner@gmail.com) 
     Commit Version: 1.6.0-4-g7f85cfe  Build Version: 1.6.7995.38578
     For more information, please see http://wiki.ros.org/sw_urdf_exporter -->
<robot
  name="industrial_mobile_robot">
  <link
    name="base_link">
    <inertial>
      <origin
        xyz="-0.000706613806839933 -1.51466277197083E-06 -0.0832416009452554"
        rpy="0 0 0" />
      <mass
        value="20.0" />
      <inertia
        ixx="3.15196293076855"
        ixy="5.75143481275299E-05"
        ixz="0.00180922884763957"
        iyy="8.27838511531717"
        iyz="-2.57084178703826E-05"
        izz="9.68878629564849" />
    </inertial>
    <visual>
      <origin
        xyz="0 0 0"
        rpy="0 0 0" />
      <geometry>
        <mesh
          filename="package://industrial_mobile_robot/meshes/base_link.STL" />
      </geometry>
      <material
        name="">
        <color
          rgba="0.792156862745098 0.819607843137255 0.933333333333333 1" />
      </material>
    </visual>
    <collision>
      <origin
        xyz="0 0 0"
        rpy="0 0 0" />
      <geometry>
        <mesh
          filename="package://industrial_mobile_robot/meshes/base_link.STL" />
      </geometry>
    </collision>
  </link>
  <link
    name="link_wh1l">
    <inertial>
      <origin
        xyz="-1.77848846760753E-11 1.3331742376721E-09 -4.83750431379271E-09"
        rpy="0 0 0" />
      <mass
        value="3.7" />
      <inertia
        ixx="0.0104142954777244"
        ixy="-8.24525130578282E-07"
        ixz="-1.28692701480105E-06"
        iyy="0.0104070240525027"
        iyz="-1.09500116009805E-05"
        izz="0.0159361237345323" />
    </inertial>
    <visual>
      <origin
        xyz="0 0 0"
        rpy="0 0 0" />
      <geometry>
        <mesh
          filename="package://industrial_mobile_robot/meshes/link_wh1l.STL" />
      </geometry>
      <material
        name="">
        <color
          rgba="0.792156862745098 0.819607843137255 0.933333333333333 1" />
      </material>
    </visual>
    <collision>
      <origin
        xyz="0 0 0"
        rpy="0 0 0" />
      <geometry>
        <mesh
          filename="package://industrial_mobile_robot/meshes/link_wh1l.STL" />
          

        
        
        
      </geometry>
      <surface>
        <friction>
          <ode>
            <mu>8000.1</mu>
            <mu2>0.4</mu2>
            <slip1>0.0</slip1>   <!-- añade resbalamiento longitudinal -->
            <slip2>0.0</slip2>   <!-- añade resbalamiento lateral -->
          </ode>
        </friction>
        <bounce>
          <restitution_coefficient>0.0</restitution_coefficient>
        </bounce>
      </surface>
    </collision>
  </link>
  <joint
    name="joint_wh1l"
    type="continuous">
    <origin
      xyz="0.31399 0.24657 -0.2201"
      rpy="-1.5708 0 3.1416" />
    <parent
      link="base_link" />
    <child
      link="link_wh1l" />
    <axis
      xyz="0 0 -1" />
  </joint>
  <link
    name="link_wh2l">
    <inertial>
      <origin
        xyz="1.24979831483962E-08 5.0021090880481E-09 5.85177903356104E-09"
        rpy="0 0 0" />
      <mass
        value="3.7" />
      <inertia
        ixx="0.0104121254993119"
        ixy="-3.42862911412428E-06"
        ixz="-6.12594235674742E-06"
        iyy="0.0104091971429616"
        iyz="-9.16790527635482E-06"
        izz="0.0159361249901461" />
    </inertial>
    <visual>
      <origin
        xyz="0 0 0"
        rpy="0 0 0" />
      <geometry>
        <mesh
          filename="package://industrial_mobile_robot/meshes/link_wh2l.STL" />
      </geometry>
      <material
        name="">
        <color
          rgba="0.792156862745098 0.819607843137255 0.933333333333333 1" />
      </material>
    </visual>
    <collision>
      <origin
        xyz="0 0 0"
        rpy="0 0 0" />
      <geometry>
        <mesh
          filename="package://industrial_mobile_robot/meshes/link_wh2l.STL" />
          
          
          
      </geometry>
      <surface>
        <friction>
          <ode>
            <mu>0.1</mu>
            <mu2>0.4</mu2>
            <slip1>0.0</slip1>   <!-- añade resbalamiento longitudinal -->
            <slip2>0.0</slip2>   <!-- añade resbalamiento lateral -->
          </ode>
        </friction>
        <bounce>
          <restitution_coefficient>0.0</restitution_coefficient>
        </bounce>
      </surface>
    </collision>
  </link>
  <joint
    name="joint_wh2l"
    type="continuous">
    <origin
      xyz="-0.31406 0.24657 -0.22008"
      rpy="-1.5708 0 3.1416" />
    <parent
      link="base_link" />
    <child
      link="link_wh2l" />
    <axis
      xyz="0 0 -1" />
  </joint>
  <link
    name="link_wh1r">
    <inertial>
      <origin
        xyz="1.31652960755346E-09 3.50002804516691E-11 -4.86615350792086E-09"
        rpy="0 0 0" />
      <mass
        value="3.7" />
      <inertia
        ixx="0.010406959646029"
        ixy="4.55456976592667E-07"
        ixz="-1.10008401379822E-05"
        iyy="0.0104143598697192"
        iyz="7.35089332306561E-07"
        izz="0.0159361237258818" />
    </inertial>
    <visual>
      <origin
        xyz="0 0 0"
        rpy="0 0 0" />
      <geometry>
        <mesh
          filename="package://industrial_mobile_robot/meshes/link_wh1r.STL" />
      </geometry>
      <material
        name="">
        <color
          rgba="0.792156862745098 0.819607843137255 0.933333333333333 1" />
      </material>
    </visual>
    <collision>
      <origin
        xyz="0 0 0"
        rpy="0 0 0" />
      <geometry>
        <mesh
          filename="package://industrial_mobile_robot/meshes/link_wh1r.STL" />
          
          
      </geometry>
      <surface>
        <friction>
          <ode>
            <mu>8000.1</mu>
            <mu2>0.4</mu2>
            <slip1>0.0</slip1>   <!-- añade resbalamiento longitudinal -->
            <slip2>0.0</slip2>   <!-- añade resbalamiento lateral -->
          </ode>
        </friction>
        <bounce>
          <restitution_coefficient>0.0</restitution_coefficient>
        </bounce>
      </surface>
    </collision>
  </link>
  <joint
    name="joint_wh1r"
    type="continuous">
    <origin
      xyz="0.3141 -0.24657 -0.21999"
      rpy="-1.5708 0 0" />
    <parent
      link="base_link" />
    <child
      link="link_wh1r" />
    <axis
      xyz="0 0 1" />
  </joint>
  <link
    name="link_wh2r">
    <inertial>
      <origin
        xyz="3.06266306759895E-09 -1.29133793103087E-08 5.73297093131586E-09"
        rpy="0 0 0" />
      <mass
        value="3.7" />
      <inertia
        ixx="0.0104102236889264"
        ixy="3.70239985220149E-06"
        ixz="-8.20151381525084E-06"
        iyy="0.0104110989680856"
        iyz="7.36973260494038E-06"
        izz="0.0159361250028455" />
    </inertial>
    <visual>
      <origin
        xyz="0 0 0"
        rpy="0 0 0" />
      <geometry>
        <mesh
          filename="package://industrial_mobile_robot/meshes/link_wh2r.STL" />
      </geometry>
      <material
        name="">
        <color
          rgba="0.792156862745098 0.819607843137255 0.933333333333333 1" />
      </material>
    </visual>
    <collision>
      <origin
        xyz="0 0 0"
        rpy="0 0 0" />
      <geometry>
        <mesh
          filename="package://industrial_mobile_robot/meshes/link_wh2r.STL" />
          
          
          
      </geometry>
      <surface>
        <friction>
          <ode>
            <mu>0.1</mu>
            <mu2>0.4</mu2>
            <slip1>0.0</slip1>   <!-- añade resbalamiento longitudinal -->
            <slip2>0.0</slip2>   <!-- añade resbalamiento lateral -->
          </ode>
        </friction>
        <bounce>
          <restitution_coefficient>0.0</restitution_coefficient>
        </bounce>
      </surface>
    </collision>
  </link>
  <joint
    name="joint_wh2r"
    type="continuous">
    <origin
      xyz="-0.31392 -0.24657 -0.21993"
      rpy="-1.5708 0 0" />
    <parent
      link="base_link" />
    <child
      link="link_wh2r" />
    <axis
      xyz="0 0 1" />
  </joint>
  <link
    name="link_cam1">
    <inertial>
      <origin
        xyz="-0.029 2.3039296165317E-19 0.00133886472296407"
        rpy="0 0 0" />
      <mass
        value="0.649382833058846" />
      <inertia
        ixx="0.00142866989558785"
        ixy="-5.3205128777967E-21"
        ixz="-6.7773672960819E-20"
        iyy="0.00126079933558785"
        iyz="4.85549597316419E-20"
        izz="0.000538293675385787" />
    </inertial>
    <visual>
      <origin
        xyz="0 0 0"
        rpy="0 0 0" />
      <geometry>
        <mesh
          filename="package://industrial_mobile_robot/meshes/link_cam1.STL" />
      </geometry>
      <material
        name="">
        <color
          rgba="0.968627450980392 0.286274509803922 0 1" />
      </material>
    </visual>
    <collision>
      <origin
        xyz="0 0 0"
        rpy="0 0 0" />
      <geometry>
        <mesh
          filename="package://industrial_mobile_robot/meshes/link_cam1.STL" />
      </geometry>
    </collision>
  </link>
  <joint
    name="joint_cam1"
    type="fixed">
    <origin
      xyz="0.37163 -8.6778E-05 0.045"
      rpy="3.1416 1.5708 0" />
    <parent
      link="base_link" />
    <child
      link="link_cam1" />
    <axis
      xyz="0 0 0" />
  </joint>
  <link
    name="link_stereo1">
    <inertial>
      <origin
        xyz="0.0390609299067655 -4.51697828717391E-10 0.00192361742920039"
        rpy="0 0 0" />
      <mass
        value="4.47983602571154" />
      <inertia
        ixx="0.0486891113790726"
        ixy="7.10767134060452E-11"
        ixz="5.25018771229614E-07"
        iyy="0.0151919553048369"
        iyz="-4.17523755856592E-09"
        izz="0.0380713030972426" />
    </inertial>
    <visual>
      <origin
        xyz="0 0 0"
        rpy="0 0 0" />
      <geometry>
        <mesh
          filename="package://industrial_mobile_robot/meshes/link_stereo1.STL" />
      </geometry>
      <material
        name="">
        <color
          rgba="0.792156862745098 0.819607843137255 0.933333333333333 1" />
      </material>
    </visual>
    <collision>
      <origin
        xyz="0 0 0"
        rpy="0 0 0" />
      <geometry>
        <mesh
          filename="package://industrial_mobile_robot/meshes/link_stereo1.STL" />
      </geometry>
    </collision>
  </link>
  <joint
    name="joint_stereo1"
    type="fixed">
    <origin
      xyz="0.15742 -8.6778E-05 0.257"
      rpy="3.1416 1.5708 0" />
    <parent
      link="base_link" />
    <child
      link="link_stereo1" />
    <axis
      xyz="0 0 0" />
  </joint>
  <link
    name="link_lidar3d1">
    <inertial>
      <origin
        xyz="-0.000343870817546166 0.0362966771287366 3.28690207281871E-06"
        rpy="0 0 0" />
      <mass
        value="0.605610172284954" />
      <inertia
        ixx="0.000667040712181393"
        ixy="1.81289461732285E-06"
        ixz="1.75260014158209E-11"
        iyy="0.000804073841920548"
        iyz="6.676371641242E-08"
        izz="0.000670924675017662" />
    </inertial>
    <visual>
      <origin
        xyz="0 0 0"
        rpy="0 0 0" />
      <geometry>
        <mesh
          filename="package://industrial_mobile_robot/meshes/link_lidar3d1.STL" />
      </geometry>
      <material
        name="">
        <color
          rgba="0.792156862745098 0.819607843137255 0.933333333333333 1" />
      </material>
    </visual>
    <collision>
      <origin
        xyz="0 0 0"
        rpy="0 0 0" />
      <geometry>
        <mesh
          filename="package://industrial_mobile_robot/meshes/link_lidar3d1.STL" />
      </geometry>
    </collision>
  </link>
  <joint
    name="joint_lidar3d1"
    type="fixed">
    <origin
      xyz="0.20047 -8.6778E-05 0.26"
      rpy="1.5708 0 3.1416" />
    <parent
      link="base_link" />
    <child
      link="link_lidar3d1" />
    <axis
      xyz="0 0 0" />
  </joint>
  <link
    name="arm_base_link">
    <inertial>
      <origin
        xyz="-0.00150709009035968 8.0407056077491E-05 0.0592787471384649"
        rpy="0 0 0" />
      <mass
        value="1.24177738140115" />
      <inertia
        ixx="0.00365451507872831"
        ixy="8.09915199553586E-07"
        ixz="-8.00546823695909E-05"
        iyy="0.00326596437131163"
        iyz="2.64852384325746E-06"
        izz="0.00500712209645328" />
    </inertial>
    <visual>
      <origin
        xyz="0 0 0"
        rpy="0 0 0" />
      <geometry>
        <mesh
          filename="package://industrial_mobile_robot/meshes/arm_base_link.STL" />
      </geometry>
      <material
        name="">
        <color
          rgba="0.792156862745098 0.819607843137255 0.933333333333333 1" />
      </material>
    </visual>
    <collision>
      <origin
        xyz="0 0 0"
        rpy="0 0 0" />
      <geometry>
        <mesh
          filename="package://industrial_mobile_robot/meshes/arm_base_link.STL" />
      </geometry>
    </collision>
  </link>
  <joint
    name="arm_base_joint"
    type="fixed">
    <origin
      xyz="0.00048196 -0.00084016 0.26"
      rpy="0 0 0" />
    <parent
      link="base_link" />
    <child
      link="arm_base_link" />
    <axis
      xyz="0 0 0" />
  </joint>
  <link
    name="link_b1">
    <inertial>
      <origin
        xyz="0.0130931670013003 -7.18303053633758E-07 0.000854712659079992"
        rpy="0 0 0" />
      <mass
        value="3.45631382183273" />
      <inertia
        ixx="0.0124436335215027"
        ixy="2.07845808632762E-07"
        ixz="-0.000227441964051589"
        iyy="0.0140385089797395"
        iyz="2.79176990399595E-08"
        izz="0.0118934102194409" />
    </inertial>
    <visual>
      <origin
        xyz="0 0 0"
        rpy="0 0 0" />
      <geometry>
        <mesh
          filename="package://industrial_mobile_robot/meshes/link_b1.STL" />
      </geometry>
      <material
        name="">
        <color
          rgba="0.792156862745098 0.819607843137255 0.933333333333333 1" />
      </material>
    </visual>
    <collision>
      <origin
        xyz="0 0 0"
        rpy="0 0 0" />
      <geometry>
        <mesh
          filename="package://industrial_mobile_robot/meshes/link_b1.STL" />
      </geometry>
    </collision>
  </link>
  <joint
    name="joint_b1"
    type="revolute">
    <origin
      xyz="0 0 0.1807"
      rpy="0 0 1.5694" />
    <parent
      link="arm_base_link" />
    <child
      link="link_b1" />
    <axis
      xyz="0 0 -1" />
    <limit
      lower="-1.57"
      upper="1.57"
      effort="330"
      velocity="3.14" />
  </joint>
  <link
    name="link_b2">
    <inertial>
      <origin
        xyz="0.189752378837526 3.68282968995267E-06 -0.000246842308868428"
        rpy="0 0 0" />
      <mass
        value="8.08742845028777" />
      <inertia
        ixx="0.0206359802008794"
        ixy="-2.77529326376294E-08"
        ixz="-0.000577937657402766"
        iyy="0.285722434787471"
        iyz="9.87703438506375E-08"
        izz="0.283055548080933" />
    </inertial>
    <visual>
      <origin
        xyz="0 0 0"
        rpy="0 0 0" />
      <geometry>
        <mesh
          filename="package://industrial_mobile_robot/meshes/link_b2.STL" />
      </geometry>
      <material
        name="">
        <color
          rgba="0.792156862745098 0.819607843137255 0.933333333333333 1" />
      </material>
    </visual>
    <collision>
      <origin
        xyz="0 0 0"
        rpy="0 0 0" />
      <geometry>
        <mesh
          filename="package://industrial_mobile_robot/meshes/link_b2.STL" />
      </geometry>
    </collision>
  </link>
  <joint
    name="joint_b2"
    type="revolute">
    <origin
      xyz="0.176 0 0"
      rpy="1.5708 -1.559 -1.5708" />
    <parent
      link="link_b1" />
    <child
      link="link_b2" />
    <axis
      xyz="0 0 -1" />
    <limit
      lower="-1.57"
      upper="1.57"
      effort="330"
      velocity="3.14" />
  </joint>
  <link
    name="link_b3">
    <inertial>
      <origin
        xyz="0.144189452218583 -0.0797185244215877 0.129861312892516"
        rpy="0 0 0" />
      <mass
        value="3.42307941031871" />
      <inertia
        ixx="0.0196048661475678"
        ixy="0.0261731624319093"
        ixz="-0.00320584664482447"
        iyy="0.052475384400285"
        iyz="0.00177224467455136"
        izz="0.0661062588974213" />
    </inertial>
    <visual>
      <origin
        xyz="0 0 0"
        rpy="0 0 0" />
      <geometry>
        <mesh
          filename="package://industrial_mobile_robot/meshes/link_b3.STL" />
      </geometry>
      <material
        name="">
        <color
          rgba="0.792156862745098 0.819607843137255 0.933333333333333 1" />
      </material>
    </visual>
    <collision>
      <origin
        xyz="0 0 0"
        rpy="0 0 0" />
      <geometry>
        <mesh
          filename="package://industrial_mobile_robot/meshes/link_b3.STL" />
      </geometry>
    </collision>
  </link>
  <joint
    name="joint_b3"
    type="revolute">
    <origin
      xyz="0.4784 0 0"
      rpy="0 0 3.1416" />
    <parent
      link="link_b2" />
    <child
      link="link_b3" />
    <axis
      xyz="0 0 1" />
    <limit
      lower="-1.57"
      upper="1.57"
      effort="150"
      velocity="3.14" />
  </joint>
  <link
    name="link_b4">
    <inertial>
      <origin
        xyz="-0.00162464283956537 -0.00286102429022972 0.119414075595399"
        rpy="0 0 0" />
      <mass
        value="0.953400520734031" />
      <inertia
        ixx="0.00174552490999951"
        ixy="-0.000135339271063085"
        ixz="2.29706334045983E-05"
        iyy="0.00158443507437754"
        iyz="4.04070531854285E-05"
        izz="0.00132739275040238" />
    </inertial>
    <visual>
      <origin
        xyz="0 0 0"
        rpy="0 0 0" />
      <geometry>
        <mesh
          filename="package://industrial_mobile_robot/meshes/link_b4.STL" />
      </geometry>
      <material
        name="">
        <color
          rgba="0.792156862745098 0.819607843137255 0.933333333333333 1" />
      </material>
    </visual>
    <collision>
      <origin
        xyz="0 0 0"
        rpy="0 0 0" />
      <geometry>
        <mesh
          filename="package://industrial_mobile_robot/meshes/link_b4.STL" />
      </geometry>
    </collision>
  </link>
  <joint
    name="joint_b4"
    type="revolute">
    <origin
      xyz="0.31503 -0.17245 0.1372"
      rpy="-3.1416 0 2.6364" />
    <parent
      link="link_b3" />
    <child
      link="link_b4" />
    <axis
      xyz="0 0 1" />
    <limit
      lower="-1.57"
      upper="1.57"
      effort="54"
      velocity="3.14" />
  </joint>
  <link
    name="link_b5">
    <inertial>
      <origin
        xyz="0.110246571921961 0.00173798640074974 -1.56245200083616E-07"
        rpy="0 0 0" />
      <mass
        value="0.854428409804227" />
      <inertia
        ixx="0.00122608147274521"
        ixy="-3.70945044826588E-05"
        ixz="1.8095845969311E-09"
        iyy="0.00112478685814982"
        iyz="1.22656849427909E-08"
        izz="0.00143902109632303" />
    </inertial>
    <visual>
      <origin
        xyz="0 0 0"
        rpy="0 0 0" />
      <geometry>
        <mesh
          filename="package://industrial_mobile_robot/meshes/link_b5.STL" />
      </geometry>
      <material
        name="">
        <color
          rgba="0.792156862745098 0.819607843137255 0.933333333333333 1" />
      </material>
    </visual>
    <collision>
      <origin
        xyz="0 0 0"
        rpy="0 0 0" />
      <geometry>
        <mesh
          filename="package://industrial_mobile_robot/meshes/link_b5.STL" />
      </geometry>
    </collision>
  </link>
  <joint
    name="joint_b5"
    type="revolute">
    <origin
      xyz="-0.00085954 -0.0015118 0.13535"
      rpy="-3.1416 0 -2.0878" />
    <parent
      link="link_b4" />
    <child
      link="link_b5" />
    <axis
      xyz="1 0 0" />
    <limit
      lower="-1.57"
      upper="1.57"
      effort="54"
      velocity="3.14" />
  </joint>
  <link
    name="link_b6">
    <inertial>
      <origin
        xyz="-5.9294004554955E-05 -5.15889062889796E-05 0.0846631442041097"
        rpy="0 0 0" />
      <mass
        value="0.350538554211854" />
      <inertia
        ixx="0.000264858740543648"
        ixy="4.69574983805387E-07"
        ixz="3.90167976384276E-08"
        iyy="0.000264726273921372"
        iyz="3.37747313999152E-08"
        izz="0.00034747848189182" />
    </inertial>
    <visual>
      <origin
        xyz="0 0 0"
        rpy="0 0 0" />
      <geometry>
        <mesh
          filename="package://industrial_mobile_robot/meshes/link_b6.STL" />
      </geometry>
      <material
        name="">
        <color
          rgba="0.792156862745098 0.819607843137255 0.933333333333333 1" />
      </material>
    </visual>
    <collision>
      <origin
        xyz="0 0 0"
        rpy="0 0 0" />
      <geometry>
        <mesh
          filename="package://industrial_mobile_robot/meshes/link_b6.STL" />
      </geometry>
    </collision>
  </link>
  <joint
    name="joint_b6"
    type="revolute">
    <origin
      xyz="0.11985 0 0"
      rpy="1.5708 0.0013732 -3.1416" />
    <parent
      link="link_b5" />
    <child
      link="link_b6" />
    <axis
      xyz="0 0 -1" />
    <limit
      lower="-1.57"
      upper="1.57"
      effort="28"
      velocity="3.14" />
  </joint>
  <link
    name="link_b7">
    <inertial>
      <origin
        xyz="-0.0357959657263475 0.000320445657188501 -0.0465976153788997"
        rpy="0 0 0" />
      <mass
        value="2.75184405159635" />
      <inertia
        ixx="0.00690734990428444"
        ixy="-1.18291184041857E-08"
        ixz="5.54685652140436E-06"
        iyy="0.0141969093433405"
        iyz="-8.94270280914313E-08"
        izz="0.0204939437753343" />
    </inertial>
    <visual>
      <origin
        xyz="0 0 0"
        rpy="0 0 0" />
      <geometry>
        <mesh
          filename="package://industrial_mobile_robot/meshes/link_b7.STL" />
      </geometry>
      <material
        name="">
        <color
          rgba="0.792156862745098 0.819607843137255 0.933333333333333 1" />
      </material>
    </visual>
    <collision>
      <origin
        xyz="0 0 0"
        rpy="0 0 0" />
      <geometry>
        <mesh
          filename="package://industrial_mobile_robot/meshes/link_b7.STL" />
      </geometry>
    </collision>
  </link>
  <joint
    name="joint_b7"
    type="fixed">
    <origin
      xyz="0.0048215 0.0010239 0.11035"
      rpy="3.1416 0 3.1416" />
    <parent
      link="link_b6" />
    <child
      link="link_b7" />
    <axis
      xyz="0 0 0" />
  </joint>
  
  <gazebo>
     <plugin filename="libignition-gazebo-diff-drive-system.so" name="ignition::gazebo::systems::DiffDrive">
      <left_joint>joint_wh1l</left_joint>
      <left_joint>joint_wh2l</left_joint>
      
      <right_joint>joint_wh1r</right_joint>
      <right_joint>joint_wh2r</right_joint>

      <!-- Dimensiones físicas -->
      <wheel_separation>0.55</wheel_separation> <!-- distancia entre ruedas -->
      <wheel_radius>0.126</wheel_radius>           <!-- radio de la rueda -->

      <!-- Control -->
      <topic>/cmd_vel</topic>
      <odom_topic>/odom</odom_topic>
      <odom_frame>odom</odom_frame>
      <base_frame>base_link</base_frame>
      <publish_odom>true</publish_odom>
      <publish_tf>true</publish_tf>

      <!-- Parámetros adicionales -->
      <max_wheel_torque>1000</max_wheel_torque>
      <!--max_linear_accel>20.0</max_linear_accel>
      <max_angular_accel>0.01</max_angular_accel>-->
    </plugin>


    <plugin filename="ignition-gazebo-joint-state-publisher-system" name="ignition::gazebo::systems::JointStatePublisher">
      <topic>/joint_states</topic>
    </plugin>
    
    <plugin filename="libignition-gazebo-joint-position-controller-system.so" name="ignition::gazebo::systems::JointPositionController">
      <joint_name>joint_b1</joint_name>
      <topic>/joint_b1/cmd_pos</topic>
      <p_gain>150.0</p_gain>
      <i_gain>0.1</i_gain>
      <d_gain>57.4</d_gain>
    </plugin>

    <plugin filename="libignition-gazebo-joint-position-controller-system.so" name="ignition::gazebo::systems::JointPositionController">
      <joint_name>joint_b2</joint_name>
      <topic>/joint_b2/cmd_pos</topic>
      <p_gain>160.0</p_gain>
      <i_gain>0.1</i_gain>
      <d_gain>27.4</d_gain>
    </plugin>

    <plugin filename="libignition-gazebo-joint-position-controller-system.so" name="ignition::gazebo::systems::JointPositionController">
      <joint_name>joint_b3</joint_name>
      <topic>/joint_b3/cmd_pos</topic>
      <p_gain>180.0</p_gain>
      <i_gain>0.1</i_gain>
      <d_gain>27.4</d_gain>
    </plugin>
    
    <plugin filename="libignition-gazebo-joint-position-controller-system.so" name="ignition::gazebo::systems::JointPositionController">
      <joint_name>joint_b4</joint_name>
      <topic>/joint_b4/cmd_pos</topic>
      <p_gain>190.0</p_gain>
      <i_gain>0.1</i_gain>
      <d_gain>40.4</d_gain>
    </plugin>
    
    <plugin filename="libignition-gazebo-joint-position-controller-system.so" name="ignition::gazebo::systems::JointPositionController">
      <joint_name>joint_b5</joint_name>
      <topic>/joint_b5/cmd_pos</topic>
      <p_gain>190.0</p_gain>
      <i_gain>0.1</i_gain>
      <d_gain>27.4</d_gain>
    </plugin>
    
    <plugin filename="libignition-gazebo-joint-position-controller-system.so" name="ignition::gazebo::systems::JointPositionController">
      <joint_name>joint_b6</joint_name>
      <topic>/joint_b6/cmd_pos</topic>
      <p_gain>90.0</p_gain>
      <i_gain>0.1</i_gain>
      <d_gain>72.4</d_gain>
    </plugin>
  </gazebo>
</robot>
